<?xml version="1.0" encoding="utf-8"?>
<!-- This URDF was automatically created by SolidWorks to URDF Exporter! Originally created by Stephen Brawner (brawner@gmail.com) 
     Commit Version: 1.6.0-4-g7f85cfe  Build Version: 1.6.7995.38578
     For more information, please see http://wiki.ros.org/sw_urdf_exporter -->
<robot
  name="dj_robotarm">
  <link
    name="base_link">
    <inertial>
      <origin
        xyz="4.5504E-18 -4.8293E-19 0.01353"
        rpy="0 0 0" />
      <mass
        value="0.062485" />
      <inertia
        ixx="1.8907E-05"
        ixy="4.8117E-38"
        ixz="1.8975E-21"
        iyy="2.4507E-05"
        iyz="2.3539E-22"
        izz="2.755E-05" />
    </inertial>
    <visual>
      <origin
        xyz="0 0 0"
        rpy="0 0 0" />
      <geometry>
        <mesh
          filename="package://dj_robotarm/meshes/base_link.STL" />
      </geometry>
      <material
        name="">
        <color
          rgba="0.79216 0.81961 0.93333 1" />
      </material>
    </visual>
    <collision>
      <origin
        xyz="0 0 0"
        rpy="0 0 0" />
      <geometry>
        <mesh
          filename="package://dj_robotarm/meshes/base_link.STL" />
      </geometry>
    </collision>
  </link>
  <link
    name="shoulder_link">
    <inertial>
      <origin
        xyz="0.00050717 0.020254 -9.9779E-18"
        rpy="0 0 0" />
      <mass
        value="0.063879" />
      <inertia
        ixx="1.6841E-05"
        ixy="8.2342E-09"
        ixz="1.6414E-21"
        iyy="1.7953E-05"
        iyz="-6.2284E-22"
        izz="1.773E-05" />
    </inertial>
    <visual>
      <origin
        xyz="0 0 0"
        rpy="0 0 0" />
      <geometry>
        <mesh
          filename="package://dj_robotarm/meshes/shoulder_link.STL" />
      </geometry>
      <material
        name="">
        <color
          rgba="0.79216 0.81961 0.93333 1" />
      </material>
    </visual>
    <collision>
      <origin
        xyz="0 0 0"
        rpy="0 0 0" />
      <geometry>
        <mesh
          filename="package://dj_robotarm/meshes/shoulder_link.STL" />
      </geometry>
    </collision>
  </link>
  <joint
    name="shoulder_joint"
    type="continuous">
    <origin
      xyz="0 -0.035 0"
      rpy="0 1.5355 -3.1416" />
    <parent
      link="base_link" />
    <child
      link="shoulder_link" />
    <axis
      xyz="0 1 0" />
  </joint>
  <link
    name="arm_link1">
    <inertial>
      <origin
        xyz="-0.043316 6.245E-17 0.0075418"
        rpy="0 0 0" />
      <mass
        value="0.019919" />
      <inertia
        ixx="9.0705E-07"
        ixy="-4.1293E-21"
        ixz="2.8812E-07"
        iyy="1.6559E-05"
        iyz="-2.912E-22"
        izz="1.6983E-05" />
    </inertial>
    <visual>
      <origin
        xyz="0 0 0"
        rpy="0 0 0" />
      <geometry>
        <mesh
          filename="package://dj_robotarm/meshes/arm_link1.STL" />
      </geometry>
      <material
        name="">
        <color
          rgba="0.79216 0.81961 0.93333 1" />
      </material>
    </visual>
    <collision>
      <origin
        xyz="0 0 0"
        rpy="0 0 0" />
      <geometry>
        <mesh
          filename="package://dj_robotarm/meshes/arm_link1.STL" />
      </geometry>
    </collision>
  </link>
  <joint
    name="arm_joint1"
    type="continuous">
    <origin
      xyz="0.017853 0.02 0"
      rpy="-1.5708 -0.44151 -1.5708" />
    <parent
      link="shoulder_link" />
    <child
      link="arm_link1" />
    <axis
      xyz="0 0 1" />
  </joint>
  <link
    name="arm_link2">
    <inertial>
      <origin
        xyz="-0.021555 2.7756E-17 0.0066384"
        rpy="0 0 0" />
      <mass
        value="0.011134" />
      <inertia
        ixx="4.8682E-07"
        ixy="3.6925E-21"
        ixz="6.5191E-22"
        iyy="3.3135E-06"
        iyz="8.4977E-23"
        izz="3.6148E-06" />
    </inertial>
    <visual>
      <origin
        xyz="0 0 0"
        rpy="0 0 0" />
      <geometry>
        <mesh
          filename="package://dj_robotarm/meshes/arm_link2.STL" />
      </geometry>
      <material
        name="">
        <color
          rgba="0.79216 0.81961 0.93333 1" />
      </material>
    </visual>
    <collision>
      <origin
        xyz="0 0 0"
        rpy="0 0 0" />
      <geometry>
        <mesh
          filename="package://dj_robotarm/meshes/arm_link2.STL" />
      </geometry>
    </collision>
  </link>
  <joint
    name="arm_joint2"
    type="continuous">
    <origin
      xyz="-0.08 0 0.010509"
      rpy="0 0 0.94336" />
    <parent
      link="arm_link1" />
    <child
      link="arm_link2" />
    <axis
      xyz="0 0 1" />
  </joint>
</robot>